<?xml version="1.0"?>
<robot name="quadruped_robot">
<link name="torso_quadruped">
<visual>
<origin xyz="-0.036130376160144805908 0.030409909784793798249 0.0019046843051910289368" rpy="0 -0 0" />
<geometry>
<mesh filename="package://quadruped_description/quadruped/torso_quadruped.stl"/>
</geometry>
<material name="torso_quadruped_material">
<color rgba="0.61568627450980395466 0.81176470588235294379 0.92941176470588238168 1.0"/>
</material>
</visual>
<collision>
<origin xyz="-0.036130376160144805908 0.030409909784793798249 0.0019046843051910289368" rpy="0 -0 0" />
<geometry>
<mesh filename="package://quadruped_description/quadruped/torso_quadruped.stl"/>
</geometry>
</collision>
<inertial>
<origin xyz="-0.036130376160144819786 0.030409909784793829474 0.057460239860746588347" rpy="0 0 0"/>
<mass value="229.02210444669586309" />
<inertia ixx="14.921779706388115017" ixy="-1.1296212912192716166e-16"  ixz="0" iyy="14.921779706388115017" iyz="0" izz="29.30634706901237152" />
</inertial>
</link>

<link name="shoulder">
<visual>
<origin xyz="0 6.9388939039072283776e-18 0" rpy="3.141592653589793116 -0 0" />
<geometry>
<mesh filename="package://quadruped_description/quadruped/shoulder.stl"/>
</geometry>
<material name="shoulder_material">
<color rgba="0.61568627450980395466 0.81176470588235294379 0.92941176470588238168 1.0"/>
</material>
</visual>
<collision>
<origin xyz="0 6.9388939039072283776e-18 0" rpy="3.141592653589793116 -0 0" />
<geometry>
<mesh filename="package://quadruped_description/quadruped/shoulder.stl"/>
</geometry>
</collision>
<inertial>
<origin xyz="-3.7347681414163801479e-19 0.027929396093619211772 -0.095649350649350650677" rpy="0 0 0"/>
<mass value="10.885618544688634657" />
<inertia ixx="0.067417122752900543459" ixy="0"  ixz="0" iyy="0.075908462192995476703" iyz="0.0092341600956555008189" izz="0.043109319895117424737" />
</inertial>
</link>

<link name="upperlimb">
<visual>
<origin xyz="-5.5511151231257827021e-17 5.5511151231257827021e-17 0" rpy="1.570796326794896558 -1.3149924912870377765e-32 -3.9984812008411029456e-17" />
<geometry>
<mesh filename="package://quadruped_description/quadruped/upperlimb.stl"/>
</geometry>
<material name="upperlimb_material">
<color rgba="0.61568627450980395466 0.81176470588235294379 0.92941176470588238168 1.0"/>
</material>
</visual>
<collision>
<origin xyz="-5.5511151231257827021e-17 5.5511151231257827021e-17 0" rpy="1.570796326794896558 -1.3149924912870377765e-32 -3.9984812008411029456e-17" />
<geometry>
<mesh filename="package://quadruped_description/quadruped/upperlimb.stl"/>
</geometry>
</collision>
<inertial>
<origin xyz="-6.5718293427543278762e-17 -0.5 -0.041859986609857721684" rpy="0 0 0"/>
<mass value="48.066367599923843557" />
<inertia ixx="5.204489452505125513" ixy="-2.0576455936112125673e-16"  ixz="4.4077287964900002904e-32" iyy="0.15045227104254321748" iyz="4.9087921518185725796e-33" izz="5.2887141526857393004" />
</inertial>
</link>

<link name="lowerlimb">
<visual>
<origin xyz="-2.2204460492503130808e-16 1.5250000000000001332 -3.4694469519536141888e-18" rpy="1.570796326794896558 -4.4423200148186268118e-33 -3.5691229485915908773e-17" />
<geometry>
<mesh filename="package://quadruped_description/quadruped/lowerlimb.stl"/>
</geometry>
<material name="lowerlimb_material">
<color rgba="0.61568627450980395466 0.81176470588235294379 0.92941176470588238168 1.0"/>
</material>
</visual>
<collision>
<origin xyz="-2.2204460492503130808e-16 1.5250000000000001332 -3.4694469519536141888e-18" rpy="1.570796326794896558 -4.4423200148186268118e-33 -3.5691229485915908773e-17" />
<geometry>
<mesh filename="package://quadruped_description/quadruped/lowerlimb.stl"/>
</geometry>
</collision>
<inertial>
<origin xyz="-2.0372969242968028846e-16 0.86258161512027509144 -0.029947488034416901159" rpy="0 0 0"/>
<mass value="82.278311597516690767" />
<inertia ixx="21.219064546212177191" ixy="-8.7975544253650715496e-16"  ixz="1.2567331365641392603e-17" iyy="0.32911778625415522015" iyz="-0.58453590065355065519" izz="21.292856017780909639" />
</inertial>
</link>

<joint name="lowerlimb1" type="revolute">
<origin xyz="2.7755575615628913511e-17 -1.000000000000000222 3.4694469519536141888e-18" rpy="-3.141592653589793116 7.9073280062811715521e-17 -2.4434609527920607697" />
<parent link="upperlimb" />
<child link="lowerlimb" />
<axis xyz="0 0 1"/>
<limit effort="1" velocity="20" lower="-2.0943951023931952626" upper="-0.69813170079773179122"/>
<joint_properties friction="0.0"/>
</joint>

<joint name="upperlimb1" type="revolute">
<origin xyz="0 6.9388939039072283776e-18 -0.1500000000000000222" rpy="1.570796326794896558 0.34906585039886578459 3.141592653589793116" />
<parent link="shoulder" />
<child link="upperlimb" />
<axis xyz="0 0 1"/>
<limit effort="1" velocity="20" lower="-1.570796326794896558" upper="-0.34906585039886589561"/>
<joint_properties friction="0.0"/>
</joint>

<joint name="shoulder1" type="revolute">
<origin xyz="0.3638696238398552163 0.030409909784793860699 0.15190468430519105114" rpy="3.141592653589793116 -0 0" />
<parent link="torso_quadruped" />
<child link="shoulder" />
<axis xyz="0 0 1"/>
<limit effort="1" velocity="20" lower="-0.785398163397448279" upper="0.785398163397448279"/>
<joint_properties friction="0.0"/>
</joint>

<link name="shoulder_2">
<visual>
<origin xyz="0 6.9388939039072283776e-18 0" rpy="3.141592653589793116 -0 0" />
<geometry>
<mesh filename="package://quadruped_description/quadruped/shoulder.stl"/>
</geometry>
<material name="shoulder_material">
<color rgba="0.61568627450980395466 0.81176470588235294379 0.92941176470588238168 1.0"/>
</material>
</visual>
<collision>
<origin xyz="0 6.9388939039072283776e-18 0" rpy="3.141592653589793116 -0 0" />
<geometry>
<mesh filename="package://quadruped_description/quadruped/shoulder.stl"/>
</geometry>
</collision>
<inertial>
<origin xyz="-3.7347681414163801479e-19 0.027929396093619211772 -0.095649350649350650677" rpy="0 0 0"/>
<mass value="10.885618544688634657" />
<inertia ixx="0.067417122752900543459" ixy="0"  ixz="0" iyy="0.075908462192995476703" iyz="0.0092341600956555008189" izz="0.043109319895117424737" />
</inertial>
</link>

<link name="upperlimb_2">
<visual>
<origin xyz="0 0 0" rpy="1.570796326794896558 -1.1855079276096799659e-32 -3.9984812008411029456e-17" />
<geometry>
<mesh filename="package://quadruped_description/quadruped/upperlimb.stl"/>
</geometry>
<material name="upperlimb_material">
<color rgba="0.61568627450980395466 0.81176470588235294379 0.92941176470588238168 1.0"/>
</material>
</visual>
<collision>
<origin xyz="0 0 0" rpy="1.570796326794896558 -1.1855079276096799659e-32 -3.9984812008411029456e-17" />
<geometry>
<mesh filename="package://quadruped_description/quadruped/upperlimb.stl"/>
</geometry>
</collision>
<inertial>
<origin xyz="-1.0207142196285454822e-17 -0.50000000000000011102 -0.041859986609857721684" rpy="0 0 0"/>
<mass value="48.066367599923843557" />
<inertia ixx="5.204489452505125513" ixy="-2.0576455936112125673e-16"  ixz="1.761713455697647143e-32" iyy="0.15045227104254321748" iyz="1.6475742977812467937e-32" izz="5.2887141526857393004" />
</inertial>
</link>

<link name="lowerlimb_2">
<visual>
<origin xyz="2.2204460492503130808e-16 1.5249999999999999112 0" rpy="1.570796326794896558 1.0013468350804833277e-32 -1.8606385163937140812e-17" />
<geometry>
<mesh filename="package://quadruped_description/quadruped/lowerlimb.stl"/>
</geometry>
<material name="lowerlimb_material">
<color rgba="0.61568627450980395466 0.81176470588235294379 0.92941176470588238168 1.0"/>
</material>
</visual>
<collision>
<origin xyz="2.2204460492503130808e-16 1.5249999999999999112 0" rpy="1.570796326794896558 1.0013468350804833277e-32 -1.8606385163937140812e-17" />
<geometry>
<mesh filename="package://quadruped_description/quadruped/lowerlimb.stl"/>
</geometry>
</collision>
<inertial>
<origin xyz="2.2599322154159233807e-16 0.86258161512027475837 -0.029947488034416901159" rpy="0 0 0"/>
<mass value="82.278311597516690767" />
<inertia ixx="21.219064546212177191" ixy="-5.1009323784545656794e-16"  ixz="-1.0987671349230024569e-19" iyy="0.32911778625415522015" iyz="-0.58453590065355065519" izz="21.292856017780909639" />
</inertial>
</link>

<joint name="lowerlimb2" type="revolute">
<origin xyz="1.1102230246251565404e-16 -0.99999999999999988898 -6.9388939039072283776e-18" rpy="-3.141592653589793116 7.9073280062811740173e-17 -2.4434609527920607697" />
<parent link="upperlimb_2" />
<child link="lowerlimb_2" />
<axis xyz="0 0 1"/>
<limit effort="1" velocity="20" lower="-2.0943951023931952626" upper="-0.69813170079773179122"/>
<joint_properties friction="0.0"/>
</joint>

<joint name="upperlimb2" type="revolute">
<origin xyz="0 6.9388939039072283776e-18 -0.1500000000000000222" rpy="1.570796326794896558 0.34906585039886578459 3.141592653589793116" />
<parent link="shoulder_2" />
<child link="upperlimb_2" />
<axis xyz="0 0 1"/>
<limit effort="1" velocity="20" lower="-1.570796326794896558" upper="-0.34906585039886589561"/>
<joint_properties friction="0.0"/>
</joint>

<joint name="shoulder2" type="revolute">
<origin xyz="-0.036130376160144812847 0.43040990978479387596 0.15190468430519105114" rpy="3.141592653589793116 -0 1.570796326794896558" />
<parent link="torso_quadruped" />
<child link="shoulder_2" />
<axis xyz="0 0 1"/>
<limit effort="1" velocity="20" lower="-0.785398163397448279" upper="0.785398163397448279"/>
<joint_properties friction="0.0"/>
</joint>

<link name="shoulder_3">
<visual>
<origin xyz="0 6.9388939039072283776e-18 0" rpy="3.141592653589793116 -0 0" />
<geometry>
<mesh filename="package://quadruped_description/quadruped/shoulder.stl"/>
</geometry>
<material name="shoulder_material">
<color rgba="0.61568627450980395466 0.81176470588235294379 0.92941176470588238168 1.0"/>
</material>
</visual>
<collision>
<origin xyz="0 6.9388939039072283776e-18 0" rpy="3.141592653589793116 -0 0" />
<geometry>
<mesh filename="package://quadruped_description/quadruped/shoulder.stl"/>
</geometry>
</collision>
<inertial>
<origin xyz="-3.7347681414163801479e-19 0.027929396093619211772 -0.095649350649350650677" rpy="0 0 0"/>
<mass value="10.885618544688634657" />
<inertia ixx="0.067417122752900543459" ixy="0"  ixz="0" iyy="0.075908462192995476703" iyz="0.0092341600956555008189" izz="0.043109319895117424737" />
</inertial>
</link>

<link name="upperlimb_3">
<visual>
<origin xyz="2.7755575615628913511e-17 1 0" rpy="1.570796326794896558 -8.6932864651471068725e-33 -3.9984812008411029456e-17" />
<geometry>
<mesh filename="package://quadruped_description/quadruped/upperlimb.stl"/>
</geometry>
<material name="upperlimb_material">
<color rgba="0.61568627450980395466 0.81176470588235294379 0.92941176470588238168 1.0"/>
</material>
</visual>
<collision>
<origin xyz="2.7755575615628913511e-17 1 0" rpy="1.570796326794896558 -8.6932864651471068725e-33 -3.9984812008411029456e-17" />
<geometry>
<mesh filename="package://quadruped_description/quadruped/upperlimb.stl"/>
</geometry>
</collision>
<inertial>
<origin xyz="1.754843341934346177e-17 0.49999999999999983347 -0.041859986609857721684" rpy="0 0 0"/>
<mass value="48.066367599923843557" />
<inertia ixx="5.204489452505125513" ixy="-2.0576455936112125673e-16"  ixz="7.4498606489908905733e-32" iyy="0.15045227104254321748" iyz="1.6391864425466884528e-32" izz="5.2887141526857393004" />
</inertial>
</link>

<link name="lowerlimb_3">
<visual>
<origin xyz="2.2204460492503130808e-16 1.5250000000000001332 0" rpy="1.570796326794896558 -5.7347221802616316163e-34 -3.5691229485915908773e-17" />
<geometry>
<mesh filename="package://quadruped_description/quadruped/lowerlimb.stl"/>
</geometry>
<material name="lowerlimb_material">
<color rgba="0.61568627450980395466 0.81176470588235294379 0.92941176470588238168 1.0"/>
</material>
</visual>
<collision>
<origin xyz="2.2204460492503130808e-16 1.5250000000000001332 0" rpy="1.570796326794896558 -5.7347221802616316163e-34 -3.5691229485915908773e-17" />
<geometry>
<mesh filename="package://quadruped_description/quadruped/lowerlimb.stl"/>
</geometry>
</collision>
<inertial>
<origin xyz="2.4035951742038230305e-16 0.86258161512027509144 -0.029947488034416901159" rpy="0 0 0"/>
<mass value="82.278311597516690767" />
<inertia ixx="21.219064546212177191" ixy="-8.7975544253650715496e-16"  ixz="1.2567331365641338677e-17" iyy="0.32911778625415522015" iyz="-0.58453590065355065519" izz="21.292856017780909639" />
</inertial>
</link>

<joint name="lowerlimb3" type="revolute">
<origin xyz="8.3266726846886740532e-17 1.000000000000000222 -6.9388939039072283776e-18" rpy="3.141592653589793116 4.3391399851923562056e-17 0.69813170079773245735" />
<parent link="upperlimb_3" />
<child link="lowerlimb_3" />
<axis xyz="0 0 1"/>
<limit effort="1" velocity="20" lower="-2.0943951023931952626" upper="-0.69813170079773179122"/>
<joint_properties friction="0.0"/>
</joint>

<joint name="upperlimb3" type="revolute">
<origin xyz="-5.5511151231257827021e-17 6.9388939039072283776e-18 -0.15000000000000007772" rpy="-1.570796326794896558 -0.34906585039886578459 6.5162095139319294904e-17" />
<parent link="shoulder_3" />
<child link="upperlimb_3" />
<axis xyz="0 0 1"/>
<limit effort="1" velocity="20" lower="-1.570796326794896558" upper="-0.34906585039886589561"/>
<joint_properties friction="0.0"/>
</joint>

<joint name="shoulder3" type="revolute">
<origin xyz="-0.036130376160144798969 -0.36959009021520616844 0.15190468430519105114" rpy="3.141592653589793116 -0 -1.570796326794896558" />
<parent link="torso_quadruped" />
<child link="shoulder_3" />
<axis xyz="0 0 1"/>
<limit effort="1" velocity="20" lower="-0.785398163397448279" upper="0.785398163397448279"/>
<joint_properties friction="0.0"/>
</joint>

<link name="shoulder_4">
<visual>
<origin xyz="0 6.9388939039072283776e-18 0" rpy="3.141592653589793116 -0 0" />
<geometry>
<mesh filename="package://quadruped_description/quadruped/shoulder.stl"/>
</geometry>
<material name="shoulder_material">
<color rgba="0.61568627450980395466 0.81176470588235294379 0.92941176470588238168 1.0"/>
</material>
</visual>
<collision>
<origin xyz="0 6.9388939039072283776e-18 0" rpy="3.141592653589793116 -0 0" />
<geometry>
<mesh filename="package://quadruped_description/quadruped/shoulder.stl"/>
</geometry>
</collision>
<inertial>
<origin xyz="-3.7347681414163801479e-19 0.027929396093619211772 -0.095649350649350650677" rpy="0 0 0"/>
<mass value="10.885618544688634657" />
<inertia ixx="0.067417122752900543459" ixy="0"  ixz="0" iyy="0.075908462192995476703" iyz="0.0092341600956555008189" izz="0.043109319895117424737" />
</inertial>
</link>

<link name="upperlimb_4">
<visual>
<origin xyz="0 0.99999999999999988898 -3.4694469519536141888e-18" rpy="1.570796326794896558 -5.6117985541275295076e-33 -3.9984812008411029456e-17" />
<geometry>
<mesh filename="package://quadruped_description/quadruped/upperlimb.stl"/>
</geometry>
<material name="upperlimb_material">
<color rgba="0.61568627450980395466 0.81176470588235294379 0.92941176470588238168 1.0"/>
</material>
</visual>
<collision>
<origin xyz="0 0.99999999999999988898 -3.4694469519536141888e-18" rpy="1.570796326794896558 -5.6117985541275295076e-33 -3.9984812008411029456e-17" />
<geometry>
<mesh filename="package://quadruped_description/quadruped/upperlimb.stl"/>
</geometry>
</collision>
<inertial>
<origin xyz="-1.0207142196285454822e-17 0.49999999999999977796 -0.041859986609857721684" rpy="0 0 0"/>
<mass value="48.066367599923843557" />
<inertia ixx="5.204489452505125513" ixy="-2.0576455936112125673e-16"  ixz="7.4758143885324723744e-32" iyy="0.15045227104254321748" iyz="1.6391864425466887265e-32" izz="5.2887141526857393004" />
</inertial>
</link>

<link name="lowerlimb_4">
<visual>
<origin xyz="2.2204460492503130808e-16 1.5249999999999999112 0" rpy="1.570796326794896558 4.8684551577683227605e-33 -1.8606385163937140812e-17" />
<geometry>
<mesh filename="package://quadruped_description/quadruped/lowerlimb.stl"/>
</geometry>
<material name="lowerlimb_material">
<color rgba="0.61568627450980395466 0.81176470588235294379 0.92941176470588238168 1.0"/>
</material>
</visual>
<collision>
<origin xyz="2.2204460492503130808e-16 1.5249999999999999112 0" rpy="1.570796326794896558 4.8684551577683227605e-33 -1.8606385163937140812e-17" />
<geometry>
<mesh filename="package://quadruped_description/quadruped/lowerlimb.stl"/>
</geometry>
</collision>
<inertial>
<origin xyz="2.2599322154159233807e-16 0.86258161512027475837 -0.029947488034416901159" rpy="0 0 0"/>
<mass value="82.278311597516690767" />
<inertia ixx="21.219064546212177191" ixy="-5.1009323784545656794e-16"  ixz="-1.0987671349228965308e-19" iyy="0.32911778625415522015" iyz="-0.58453590065355065519" izz="21.292856017780909639" />
</inertial>
</link>

<joint name="lowerlimb4" type="revolute">
<origin xyz="1.6653345369377348106e-16 0.99999999999999966693 3.4694469519536141888e-18" rpy="3.141592653589793116 4.339139985192361136e-17 0.69813170079773234633" />
<parent link="upperlimb_4" />
<child link="lowerlimb_4" />
<axis xyz="0 0 1"/>
<limit effort="1" velocity="20" lower="-2.0943951023931952626" upper="-0.69813170079773179122"/>
<joint_properties friction="0.0"/>
</joint>

<joint name="upperlimb4" type="revolute">
<origin xyz="-5.5511151231257827021e-17 6.9388939039072283776e-18 -0.14999999999999985567" rpy="-1.570796326794896558 -0.34906585039886578459 6.5162095139319294904e-17" />
<parent link="shoulder_4" />
<child link="upperlimb_4" />
<axis xyz="0 0 1"/>
<limit effort="1" velocity="20" lower="-1.570796326794896558" upper="-0.34906585039886589561"/>
<joint_properties friction="0.0"/>
</joint>

<joint name="shoulder4" type="revolute">
<origin xyz="-0.43613037616014482811 0.030409909784793846821 0.15190468430519105114" rpy="3.141592653589793116 -0 3.141592653589793116" />
<parent link="torso_quadruped" />
<child link="shoulder_4" />
<axis xyz="0 0 1"/>
<limit effort="1" velocity="20" lower="-0.785398163397448279" upper="0.785398163397448279"/>
<joint_properties friction="0.0"/>
</joint>


</robot>
